#VRML_SIM R2025a utf8

EXTERNPROTO "https://raw.githubusercontent.com/cyberbotics/webots/R2025a/projects/objects/backgrounds/protos/TexturedBackground.proto"
EXTERNPROTO "https://raw.githubusercontent.com/cyberbotics/webots/R2025a/projects/objects/backgrounds/protos/TexturedBackgroundLight.proto"
EXTERNPROTO "https://raw.githubusercontent.com/cyberbotics/webots/R2025a/projects/objects/floors/protos/RectangleArena.proto"

WorldInfo {
}
Viewpoint {
  orientation -0.20648785154333651 -0.2438195897542876 0.9475836505644596 5.21787031176339
  position -9.016729696623539 9.736856435749857 3.3853666368264097
}
TexturedBackground {
}
TexturedBackgroundLight {
}
RectangleArena {
  floorSize 10 7
  floorTileSize 10 7
  floorAppearance PBRAppearance {
    baseColorMap ImageTexture {
      url [
        "../track.jpeg"
      ]
    }
    roughness 1
  }
}
Solid {
  translation 0 -0.11 1.45
  children [
    Shape {
      appearance PBRAppearance {
        baseColor 0 0.333333 1
        roughness 1
        metalness 0
      }
      geometry DEF bx Box {
        size 0.5 0.5 0.5
      }
    }
  ]
  boundingObject Shape {
    geometry Box {
      size 0.5 0.5 0.3
    }
  }
  physics Physics {
  }
}
Robot {
  translation 3.29031 2.39 0.0993409
  rotation 0 0 1 3.14159
  children [
    DistanceSensor {
      translation 0.15 0.15 -0.09
      rotation 0 1 0 1.5708
      children [
        DEF b2 Shape {
          appearance PBRAppearance {
            baseColor 0.7 1 0.3
          }
          geometry Box {
            size 0.01 0.01 0.01
          }
        }
      ]
      name "ds_right"
      boundingObject USE b2
      lookupTable [
        0 0 0
        0.04 1000 0
      ]
      type "infra-red"
    }
    DistanceSensor {
      translation 0.15 -0.15 -0.09
      rotation 0 1 0 1.5708
      children [
        Shape {
          appearance PBRAppearance {
            baseColor 0.7 1 0.3
          }
          geometry Box {
            size 0.01 0.01 0.01
          }
        }
      ]
      name "ds_left"
      boundingObject USE b2
      lookupTable [
        0 0 0
        0.04 1000 0
      ]
      type "infra-red"
    }
    BallJoint {
      jointParameters BallJointParameters {
        anchor 0.1 0 -0.08
      }
      endPoint Solid {
        translation 0.1 -6.312439900404667e-11 -0.0800406
        rotation -1.3455989332199983e-06 -0.9999999999886969 -4.5602194455418776e-06 1.1325332393447523
        children [
          Shape {
            appearance PBRAppearance {
            }
            geometry DEF sp Sphere {
              radius 0.02
              subdivision 3
            }
          }
        ]
        name "solid(2)"
        boundingObject USE sp
        physics Physics {
        }
      }
    }
    HingeJoint {
      jointParameters HingeJointParameters {
        axis 0 1 0
        anchor -0.1 -0.123 -0.05
      }
      device [
        RotationalMotor {
          name "right_motor"
          maxVelocity 1000
        }
      ]
      endPoint Solid {
        translation -0.1 -0.123 -0.050011200000000006
        rotation -1 0 0 1.5708000087477523
        children [
          DEF cil2 Shape {
            appearance PBRAppearance {
              baseColor 1 0.2 1
            }
            geometry Cylinder {
              height 0.02
              radius 0.05
            }
          }
        ]
        name "solid(1)"
        boundingObject USE cil2
        physics Physics {
        }
      }
    }
    HingeJoint {
      jointParameters HingeJointParameters {
        axis 0 1 0
        anchor -0.1 0.123 -0.05
      }
      device [
        RotationalMotor {
          name "left_motor"
          maxVelocity 1000
        }
      ]
      endPoint Solid {
        translation -0.1 0.123 -0.05
        rotation -1 -2.35513435228286e-16 7.850447840942867e-17 1.5708000087477236
        children [
          DEF cil Shape {
            appearance PBRAppearance {
              baseColor 1 0.4 1
            }
            geometry Cylinder {
              height 0.02
              radius 0.05
            }
          }
        ]
        boundingObject USE cil
        physics Physics {
        }
      }
    }
    Shape {
      appearance PBRAppearance {
        baseColor 0 1 0.5
      }
      geometry DEF box Box {
        size 0.3 0.2 0.02
      }
    }
  ]
  boundingObject USE box
  physics Physics {
  }
  controller "linefollow1"
}
